Workbook

Sheet Инфографика
A1: ИСЛАМ · БОЛЬШАЯ ХРОНОЛОГИЯ 570 — 2026 | DX1: ٱلْإِسْلَام
A2: Эпохи, события, державы, все ветви и расколы, школы права и вероучения, суфийские ордены, реформаторские и новые движения, личности. Столбец = десятилетие; полоса строится автоматически из столбцов «Начало» и «Конец».
A3: Цвета: ■ сунниты ■ шииты ■ хариджиты/ибадиты ■ калам и философия ■ суфизм ■ реформизм и новые движения ■ гетеродоксия / спорный статус ■ экстремизм (справочно) · ▶ — течение существует сегодня
B5: ЭПОХИ | J5: Пророк | Q5: Праведные халифы | T5: Омейяды | AB5: Аббасидский расцвет | AV5: Раздробленность · Буиды · Сельджуки · крестоносцы | CA5: Монголы · мамлюки · Тимуриды | CY5: Пороховые империи | EC5: Колониализм и реформы | EP5: Национальные государства | EU5: Исламское возрождение и глобализация
J6: 570 | M6: 600 | R6: 650 | W6: 700 | AB6: 750 | AG6: 800 | AL6: 850 | AQ6: 900 | AV6: 950 | BA6: 1000 | BF6: 1050 | BK6: 1100 | BP6: 1150 | BU6: 1200 | BZ6: 1250 | CE6: 1300 | CJ6: 1350 | CO6: 1400 | CT6: 1450 | CY6: 1500 | DD6: 1550 | DI6: 1600 | DN6: 1650 | DS6: 1700 | DX6: 1750 | EC6: 1800 | EH6: 1850 | EM6: 1900 | ER6: 1950 | EW6: 2000 | EZ6: ▶
J7: 570 | K7: 580 | L7: 590 | M7: 600 | N7: 610 | O7: 620 | P7: 630 | Q7: 640 | R7: 650 | S7: 660 | T7: 670 | U7: 680 | V7: 690 | W7: 700 | X7: 710 | Y7: 720 | Z7: 730 | AA7: 740 | AB7: 750 | AC7: 760 | AD7: 770 | AE7: 780 | AF7: 790 | AG7: 800 | AH7: 810 | AI7: 820 | AJ7: 830 | AK7: 840 | AL7: 850 | AM7: 860 | AN7: 870 | AO7: 880 | AP7: 890 | AQ7: 900 | AR7: 910 | AS7: 920 | AT7: 930 | AU7: 940 | AV7: 950 | AW7: 960 | AX7: 970 | AY7: 980 | AZ7: 990 | BA7: 1000 | BB7: 1010 | BC7: 1020 | BD7: 1030 | BE7: 1040 | BF7: 1050 | BG7: 1060 | BH7: 1070 | BI7: 1080 | BJ7: 1090 | BK7: 1100 | BL7: 1110 | BM7: 1120 | BN7: 1130 | BO7: 1140 | BP7: 1150 | BQ7: 1160 | BR7: 1170 | BS7: 1180 | BT7: 1190 | BU7: 1200 | BV7: 1210 | BW7: 1220 | BX7: 1230 | BY7: 1240 | BZ7: 1250 | CA7: 1260 | CB7: 1270 | CC7: 1280 | CD7: 1290 | CE7: 1300 | CF7: 1310 | CG7: 1320 | CH7: 1330 | CI7: 1340 | CJ7: 1350 | CK7: 1360 | CL7: 1370 | CM7: 1380 | CN7: 1390 | CO7: 1400 | CP7: 1410 | CQ7: 1420 | CR7: 1430 | CS7: 1440 | CT7: 1450 | CU7: 1460 | CV7: 1470 | CW7: 1480 | CX7: 1490 | CY7: 1500 | CZ7: 1510 | DA7: 1520 | DB7: 1530 | DC7: 1540 | DD7: 1550 | DE7: 1560 | DF7: 1570 | DG7: 1580 | DH7: 1590 | DI7: 1600 | DJ7: 1610 | DK7: 1620 | DL7: 1630 | DM7: 1640 | DN7: 1650 | DO7: 1660 | DP7: 1670 | DQ7: 1680 | DR7: 1690 | DS7: 1700 | DT7: 1710 | DU7: 1720 | DV7: 1730 | DW7: 1740 | DX7: 1750 | DY7: 1760 | DZ7: 1770 | EA7: 1780 | EB7: 1790 | EC7: 1800 | ED7: 1810 | EE7: 1820 | EF7: 1830 | EG7: 1840 | EH7: 1850 | EI7: 1860 | EJ7: 1870 | EK7: 1880 | EL7: 1890 | EM7: 1900 | EN7: 1910 | EO7: 1920 | EP7: 1930 | EQ7: 1940 | ER7: 1950 | ES7: 1960 | ET7: 1970 | EU7: 1980 | EV7: 1990 | EW7: 2000 | EX7: 2010 | EY7: 2020
A8: Раздел | B8: Название (течение, держава, событие, личность) | C8: Начало | D8: Конец | E8: Статус | F8: Лет | G8: Откололось от / примечание | H8: Цвет
A9: ■ КЛЮЧЕВЫЕ СОБЫТИЯ | B9: Даты, изменившие ход истории уммы
A10: Ключевые события | B10: Рождение Мухаммада | C10: 570 | D10: 570 | E10: =IF(C10=D10,"событие",IF(D10>=2026,IF(A10="Личности","жив","существует"),"в прошлом")) -> событие | F10: =IF(C10=D10,"",D10-C10) | H10: ev2 | EZ10: =IF(AND(D10>=2026,C10<D10),"▶","")
A11: Ключевые события | B11: Первое откровение | C11: 610 | D11: 610 | E11: =IF(C11=D11,"событие",IF(D11>=2026,IF(A11="Личности","жив","существует"),"в прошлом")) -> событие | F11: =IF(C11=D11,"",D11-C11) | H11: ev2 | EZ11: =IF(AND(D11>=2026,C11<D11),"▶","")
A12: Ключевые события | B12: Хиджра — 1 г. х. | C12: 622 | D12: 622 | E12: =IF(C12=D12,"событие",IF(D12>=2026,IF(A12="Личности","жив","существует"),"в прошлом")) -> событие | F12: =IF(C12=D12,"",D12-C12) | H12: ev2 | EZ12: =IF(AND(D12>=2026,C12<D12),"▶","")
A13: Ключевые события | B13: Бадр | C13: 624 | D13: 624 | E13: =IF(C13=D13,"событие",IF(D13>=2026,IF(A13="Личности","жив","существует"),"в прошлом")) -> событие | F13: =IF(C13=D13,"",D13-C13) | H13: ev | EZ13: =IF(AND(D13>=2026,C13<D13),"▶","")
A14: Ключевые события | B14: Взятие Мекки | C14: 630 | D14: 630 | E14: =IF(C14=D14,"событие",IF(D14>=2026,IF(A14="Личности","жив","существует"),"в прошлом")) -> событие | F14: =IF(C14=D14,"",D14-C14) | H14: ev | EZ14: =IF(AND(D14>=2026,C14<D14),"▶","")
A15: Ключевые события | B15: Смерть Пророка | C15: 632 | D15: 632 | E15: =IF(C15=D15,"событие",IF(D15>=2026,IF(A15="Личности","жив","существует"),"в прошлом")) -> событие | F15: =IF(C15=D15,"",D15-C15) | H15: ev2 | EZ15: =IF(AND(D15>=2026,C15<D15),"▶","")
A16: Ключевые события | B16: Ярмук | C16: 636 | D16: 636 | E16: =IF(C16=D16,"событие",IF(D16>=2026,IF(A16="Личности","жив","существует"),"в прошлом")) -> событие | F16: =IF(C16=D16,"",D16-C16) | H16: ev | EZ16: =IF(AND(D16>=2026,C16<D16),"▶","")
A17: Ключевые события | B17: Кадисия, Иерусалим | C17: 637 | D17: 637 | E17: =IF(C17=D17,"событие",IF(D17>=2026,IF(A17="Личности","жив","существует"),"в прошлом")) -> событие | F17: =IF(C17=D17,"",D17-C17) | H17: ev | EZ17: =IF(AND(D17>=2026,C17<D17),"▶","")
A18: Ключевые события | B18: Канон Корана (Усман) | C18: 650 | D18: 650 | E18: =IF(C18=D18,"событие",IF(D18>=2026,IF(A18="Личности","жив","существует"),"в прошлом")) -> событие | F18: =IF(C18=D18,"",D18-C18) | H18: ev | EZ18: =IF(AND(D18>=2026,C18<D18),"▶","")
A19: Ключевые события | B19: Убийство Усмана | C19: 656 | D19: 656 | E19: =IF(C19=D19,"событие",IF(D19>=2026,IF(A19="Личности","жив","существует"),"в прошлом")) -> событие | F19: =IF(C19=D19,"",D19-C19) | H19: ev | EZ19: =IF(AND(D19>=2026,C19<D19),"▶","")
A20: Ключевые события | B20: Сиффин → хариджиты | C20: 657 | D20: 657 | E20: =IF(C20=D20,"событие",IF(D20>=2026,IF(A20="Личности","жив","существует"),"в прошлом")) -> событие | F20: =IF(C20=D20,"",D20-C20) | H20: ev2 | EZ20: =IF(AND(D20>=2026,C20<D20),"▶","")
A21: Ключевые события | B21: Гибель Али | C21: 661 | D21: 661 | E21: =IF(C21=D21,"событие",IF(D21>=2026,IF(A21="Личности","жив","существует"),"в прошлом")) -> событие | F21: =IF(C21=D21,"",D21-C21) | H21: ev2 | EZ21: =IF(AND(D21>=2026,C21<D21),"▶","")
... A82: Ключевые события | B82: Гибель Али Хаменеи | C82: 2026 | D82: 2026 | E82: =IF(C82=D82,"событие",IF(D82>=2026,IF(A82="Личности","жив","существует"),"в прошлом")) -> событие | F82: =IF(C82=D82,"",D82-C82) | H82: ev2 | EZ82: =IF(AND(D82>=2026,C82<D82),"▶","")
A83: ■ ДЕРЖАВЫ И ДИНАСТИИ | B83: Цвет — вероисповедание правящей династии
A84: Державы и династии | B84: Медина Пророка | C84: 622 | D84: 632 | E84: =IF(C84=D84,"событие",IF(D84>=2026,IF(A84="Личности","жив","существует"),"в прошлом")) -> в прошлом | F84: =IF(C84=D84,"",D84-C84) -> 10 | H84: gold | EZ84: =IF(AND(D84>=2026,C84<D84),"▶","")
A85: Державы и династии | B85: Праведный халифат | C85: 632 | D85: 661 | E85: =IF(C85=D85,"событие",IF(D85>=2026,IF(A85="Личности","жив","существует"),"в прошлом")) -> в прошлом | F85: =IF(C85=D85,"",D85-C85) -> 29 | H85: gold | EZ85: =IF(AND(D85>=2026,C85<D85),"▶","")
A86: Державы и династии | B86: Омейяды (Дамаск) | C86: 661 | D86: 750 | E86: =IF(C86=D86,"событие",IF(D86>=2026,IF(A86="Личности","жив","существует"),"в прошлом")) -> в прошлом | F86: =IF(C86=D86,"",D86-C86) -> 89 | H86: sun | EZ86: =IF(AND(D86>=2026,C86<D86),"▶","")
A87: Державы и династии | B87: Аббасиды (Багдад) | C87: 750 | D87: 1258 | E87: =IF(C87=D87,"событие",IF(D87>=2026,IF(A87="Личности","жив","существует"),"в прошлом")) -> в прошлом | F87: =IF(C87=D87,"",D87-C87) -> 508 | H87: sun | EZ87: =IF(AND(D87>=2026,C87<D87),"▶","")
A88: Державы и династии | B88: Кордова: эмират → халифат | C88: 756 | D88: 1031 | E88: =IF(C88=D88,"событие",IF(D88>=2026,IF(A88="Личности","жив","существует"),"в прошлом")) -> в прошлом | F88: =IF(C88=D88,"",D88-C88) -> 275 | H88: sun | EZ88: =IF(AND(D88>=2026,C88<D88),"▶","")
A89: Державы и династии | B89: Рустамиды | C89: 777 | D89: 909 | E89: =IF(C89=D89,"событие",IF(D89>=2026,IF(A89="Личности","жив","существует"),"в прошлом")) -> в прошлом | F89: =IF(C89=D89,"",D89-C89) -> 132 | H89: kha | EZ89: =IF(AND(D89>=2026,C89<D89),"▶","")
A90: Державы и династии | B90: Идрисиды | C90: 788 | D90: 974 | E90: =IF(C90=D90,"событие",IF(D90>=2026,IF(A90="Личности","жив","существует"),"в прошлом")) -> в прошлом | F90: =IF(C90=D90,"",D90-C90) -> 186 | H90: mix | EZ90: =IF(AND(D90>=2026,C90<D90),"▶","")
A91: Державы и династии | B91: Аглабиды | C91: 800 | D91: 909 | E91: =IF(C91=D91,"событие",IF(D91>=2026,IF(A91="Личности","жив","существует"),"в прошлом")) -> в прошлом | F91: =IF(C91=D91,"",D91-C91) -> 109 | H91: sun | EZ91: =IF(AND(D91>=2026,C91<D91),"▶","")
A92: Державы и династии | B92: Тахириды | C92: 821 | D92: 873 | E92: =IF(C92=D92,"событие",IF(D92>=2026,IF(A92="Личности","жив","существует"),"в прошлом")) -> в прошлом | F92: =IF(C92=D92,"",D92-C92) -> 52 | H92: sun | EZ92: =IF(AND(D92>=2026,C92<D92),"▶","")
A93: Державы и династии | B93: Караханиды | C93: 840 | D93: 1212 | E93: =IF(C93=D93,"событие",IF(D93>=2026,IF(A93="Личности","жив","существует"),"в прошлом")) -> в прошлом | F93: =IF(C93=D93,"",D93-C93) -> 372 | H93: sun | EZ93: =IF(AND(D93>=2026,C93<D93),"▶","")
A94: Державы и династии | B94: Зайдиты Табаристана | C94: 864 | D94: 928 | E94: =IF(C94=D94,"событие",IF(D94>=2026,IF(A94="Личности","жив","существует"),"в прошлом")) -> в прошлом | F94: =IF(C94=D94,"",D94-C94) -> 64 | H94: shi | EZ94: =IF(AND(D94>=2026,C94<D94),"▶","")
A95: Державы и династии | B95: Тулуниды | C95: 868 | D95: 905 | E95: =IF(C95=D95,"событие",IF(D95>=2026,IF(A95="Личности","жив","существует"),"в прошлом")) -> в прошлом | F95: =IF(C95=D95,"",D95-C95) -> 37 | H95: sun | EZ95: =IF(AND(D95>=2026,C95<D95),"▶","")
... A136: Державы и династии | B136: Талибан | C136: 2021 | D136: 2026 | E136: =IF(C136=D136,"событие",IF(D136>=2026,IF(A136="Личности","жив","существует"),"в прошлом")) -> существует | F136: =IF(C136=D136,"",D136-C136) -> 5 | H136: sun | EZ136: =IF(AND(D136>=2026,C136<D136),"▶","") -> ▶
A137: ■ ХАРИДЖИТЫ И ИБАДИТЫ | B137: Первое сектантское движение (657). Жива только ибадитская ветвь — Оман, Мзаб, Джерба, Нафуса.
A138: Хариджиты и ибадиты | B138: Мухаккима (харуриты) | C138: 657 | D138: 658 | E138: =IF(C138=D138,"событие",IF(D138>=2026,IF(A138="Личности","жив","существует"),"в прошлом")) -> в прошлом | F138: =IF(C138=D138,"",D138-C138) -> 1 | H138: kha | EZ138: =IF(AND(D138>=2026,C138<D138),"▶","")
A139: Хариджиты и ибадиты | B139: Азракиты | C139: 684 | D139: 699 | E139: =IF(C139=D139,"событие",IF(D139>=2026,IF(A139="Личности","жив","существует"),"в прошлом")) -> в прошлом | F139: =IF(C139=D139,"",D139-C139) -> 15 | G139: ← Мухаккима (харуриты) | H139: kha | EZ139: =IF(AND(D139>=2026,C139<D139),"▶","")
A140: Хариджиты и ибадиты | B140: Наджадиты | C140: 686 | D140: 693 | E140: =IF(C140=D140,"событие",IF(D140>=2026,IF(A140="Личности","жив","существует"),"в прошлом")) -> в прошлом | F140: =IF(C140=D140,"",D140-C140) -> 7 | G140: ← Мухаккима (харуриты) | H140: kha | EZ140: =IF(AND(D140>=2026,C140<D140),"▶","")
A141: Хариджиты и ибадиты | B141: Суфриты (Мидрариды, берберское восстание 740) | C141: 690 | D141: 960 | E141: =IF(C141=D141,"событие",IF(D141>=2026,IF(A141="Личности","жив","существует"),"в прошлом")) -> в прошлом | F141: =IF(C141=D141,"",D141-C141) -> 270 | G141: ← Мухаккима (харуриты) | H141: kha | EZ141: =IF(AND(D141>=2026,C141<D141),"▶","")
...

Sheet Сводка
A1: Сводка по разделам хронологии
A2: Все значения — формулы, ссылающиеся на лист «Инфографика».
A4: Раздел | B4: Всего строк | C4: Существуют / живы сегодня | D4: В прошлом / события | E4: Самое раннее начало | F4: Самое позднее начало | G4: Доля существующих
A5: Ключевые события | B5: =COUNTIF(Инфографика!$A$9:$A$334,A5) -> 73 | C5: =COUNTIFS(Инфографика!$A$9:$A$334,A5,Инфографика!$E$9:$E$334,"существует")+COUNTIFS(Инфографика!$A$9:$A$334,A5,Инфографика!$E$9:$E$334,"жив") -> 0 | D5: =B5-C5 -> 73 | E5: =_xlfn.MINIFS(Инфографика!$C$9:$C$334,Инфографика!$A$9:$A$334,A5) -> 570 | F5: =_xlfn.MAXIFS(Инфографика!$C$9:$C$334,Инфографика!$A$9:$A$334,A5) -> 2026 | G5: =IF(B5=0,"-",C5/B5) -> 0
A6: Державы и династии | B6: =COUNTIF(Инфографика!$A$9:$A$334,A6) -> 53 | C6: =COUNTIFS(Инфографика!$A$9:$A$334,A6,Инфографика!$E$9:$E$334,"существует")+COUNTIFS(Инфографика!$A$9:$A$334,A6,Инфографика!$E$9:$E$334,"жив") -> 6 | D6: =B6-C6 -> 47 | E6: =_xlfn.MINIFS(Инфографика!$C$9:$C$334,Инфографика!$A$9:$A$334,A6) -> 622 | F6: =_xlfn.MAXIFS(Инфографика!$C$9:$C$334,Инфографика!$A$9:$A$334,A6) -> 2021 | G6: =IF(B6=0,"-",C6/B6) -> 0.11320755
A7: Хариджиты и ибадиты | B7: =COUNTIF(Инфографика!$A$9:$A$334,A7) -> 7 | C7: =COUNTIFS(Инфографика!$A$9:$A$334,A7,Инфографика!$E$9:$E$334,"существует")+COUNTIFS(Инфографика!$A$9:$A$334,A7,Инфографика!$E$9:$E$334,"жив") -> 1 | D7: =B7-C7 -> 6 | E7: =_xlfn.MINIFS(Инфографика!$C$9:$C$334,Инфографика!$A$9:$A$334,A7) -> 657 | F7: =_xlfn.MAXIFS(Инфографика!$C$9:$C$334,Инфографика!$A$9:$A$334,A7) -> 784 | G7: =IF(B7=0,"-",C7/B7) -> 0.14285714
A8: Шиизм | B8: =COUNTIF(Инфографика!$A$9:$A$334,A8) -> 29 | C8: =COUNTIFS(Инфографика!$A$9:$A$334,A8,Инфографика!$E$9:$E$334,"существует")+COUNTIFS(Инфографика!$A$9:$A$334,A8,Инфографика!$E$9:$E$334,"жив") -> 15 | D8: =B8-C8 -> 14 | E8: =_xlfn.MINIFS(Инфографика!$C$9:$C$334,Инфографика!$A$9:$A$334,A8) -> 632 | F8: =_xlfn.MAXIFS(Инфографика!$C$9:$C$334,Инфографика!$A$9:$A$334,A8) -> 1992 | G8: =IF(B8=0,"-",C8/B8) -> 0.51724138
A9: Суннизм: право и вероучение | B9: =COUNTIF(Инфографика!$A$9:$A$334,A9) -> 13 | C9: =COUNTIFS(Инфографика!$A$9:$A$334,A9,Инфографика!$E$9:$E$334,"существует")+COUNTIFS(Инфографика!$A$9:$A$334,A9,Инфографика!$E$9:$E$334,"жив") -> 7 | D9: =B9-C9 -> 6 | E9: =_xlfn.MINIFS(Инфографика!$C$9:$C$334,Инфографика!$A$9:$A$334,A9) -> 632 | F9: =_xlfn.MAXIFS(Инфографика!$C$9:$C$334,Инфографика!$A$9:$A$334,A9) -> 930 | G9: =IF(B9=0,"-",C9/B9) -> 0.53846154
A10: Калам, философия, наука | B10: =COUNTIF(Инфографика!$A$9:$A$334,A10) -> 10 | C10: =COUNTIFS(Инфографика!$A$9:$A$334,A10,Инфографика!$E$9:$E$334,"существует")+COUNTIFS(Инфографика!$A$9:$A$334,A10,Инфографика!$E$9:$E$334,"жив") -> 1 | D10: =B10-C10 -> 9 | E10: =_xlfn.MINIFS(Инфографика!$C$9:$C$334,Инфографика!$A$9:$A$334,A10) -> 690 | F10: =_xlfn.MAXIFS(Инфографика!$C$9:$C$334,Инфографика!$A$9:$A$334,A10) -> 1870 | G10: =IF(B10=0,"-",C10/B10) -> 0.1
A11: Суфизм и тарикаты | B11: =COUNTIF(Инфографика!$A$9:$A$334,A11) -> 22 | C11: =COUNTIFS(Инфографика!$A$9:$A$334,A11,Инфографика!$E$9:$E$334,"существует")+COUNTIFS(Инфографика!$A$9:$A$334,A11,Инфографика!$E$9:$E$334,"жив") -> 19 | D11: =B11-C11 -> 3 | E11: =_xlfn.MINIFS(Инфографика!$C$9:$C$334,Инфографика!$A$9:$A$334,A11) -> 700 | F11: =_xlfn.MAXIFS(Инфографика!$C$9:$C$334,Инфографика!$A$9:$A$334,A11) -> 1883 | G11: =IF(B11=0,"-",C11/B11) -> 0.86363636
A12: Реформизм и новые движения | B12: =COUNTIF(Инфографика!$A$9:$A$334,A12) -> 23 | C12: =COUNTIFS(Инфографика!$A$9:$A$334,A12,Инфографика!$E$9:$E$334,"существует")+COUNTIFS(Инфографика!$A$9:$A$334,A12,Инфографика!$E$9:$E$334,"жив") -> 18 | D12: =B12-C12 -> 5 | E12: =_xlfn.MINIFS(Инфографика!$C$9:$C$334,Инфографика!$A$9:$A$334,A12) -> 1744 | F12: =_xlfn.MAXIFS(Инфографика!$C$9:$C$334,Инфографика!$A$9:$A$334,A12) -> 1987 | G12: =IF(B12=0,"-",C12/B12) -> 0.7826087
A13: Радикальный джихадизм | B13: =COUNTIF(Инфографика!$A$9:$A$334,A13) -> 5 | C13: =COUNTIFS(Инфографика!$A$9:$A$334,A13,Инфографика!$E$9:$E$334,"существует")+COUNTIFS(Инфографика!$A$9:$A$334,A13,Инфографика!$E$9:$E$334,"жив") -> 3 | D13: =B13-C13 -> 2 | E13: =_xlfn.MINIFS(Инфографика!$C$9:$C$334,Инфографика!$A$9:$A$334,A13) -> 1971 | F13: =_xlfn.MAXIFS(Инфографика!$C$9:$C$334,Инфографика!$A$9:$A$334,A13) -> 2012 | G13: =IF(B13=0,"-",C13/B13) -> 0.6
A14: Личности | B14: =COUNTIF(Инфографика!$A$9:$A$334,A14) -> 81 | C14: =COUNTIFS(Инфографика!$A$9:$A$334,A14,Инфографика!$E$9:$E$334,"существует")+COUNTIFS(Инфографика!$A$9:$A$334,A14,Инфографика!$E$9:$E$334,"жив") -> 4 | D14: =B14-C14 -> 77 | E14: =_xlfn.MINIFS(Инфографика!$C$9:$C$334,Инфографика!$A$9:$A$334,A14) -> 570 | F14: =_xlfn.MAXIFS(Инфографика!$C$9:$C$334,Инфографика!$A$9:$A$334,A14) -> 1971 | G14: =IF(B14=0,"-",C14/B14) -> 0.049382716
A15: ИТОГО | B15: =SUM(B5:B14) -> 316 | C15: =SUM(C5:C14) -> 74 | D15: =SUM(D5:D14) -> 242 | E15: =MIN(E5:E14) -> 570 | F15: =MAX(F5:F14) -> 2026 | G15: =IF(B15=0,"-",C15/B15) -> 0.23417722
A18: Мусульманский мир сегодня (оценки)
A19: Мусульман в мире, млрд (2020) | B19: 2
A20: Доля в населении Земли | B20: 0.256
A21: Сунниты, доля (оценка 85–90%) | B21: 0.875
A22: Шииты, доля (оценка 10–13%) | B22: 0.115
A23: Ибадиты, доля | B23: 0.002
A24: Государств — членов ОИС | B24: 57
A25: Прогноз численности на 2050 г., млрд | B25: 2.8
A26: Источник: Pew Research Center, «How the Global Religious Landscape Changed From 2010 to 2020» (2025); доли сунниты/шииты — середина диапазона оценок.

Sheet О документе
A1: Ислам · Большая хронология 570–2026 — Excel-версия инфографики
A3: Как читать
A4: • Лист «Инфографика»: каждая строка — событие, держава, течение или личность; цветная полоса справа показывает период существования.
A5: • Столбец «Откололось от» показывает, от какой ветви произошло течение (точка раскола).
A6: • ▶ в последнем столбце — течение или государство существует сегодня.
A7: • Фильтры в заголовке таблицы позволяют отобрать раздел, статус или период.
A9: Как редактировать
A10: • Меняйте только синие числа в столбцах «Начало» и «Конец» — полосы, статус, длительность и «Сводка» пересчитаются.
A11: • Новую строку добавляйте внутри раздела: скопируйте соседнюю строку целиком (цветовой код в скрытом столбце H задаёт цвет полосы).
A12: • Коды цветов: sun — сунниты, shi — шииты, kha — хариджиты/ибадиты, kal — калам и философия, suf — суфизм, mod — реформизм, het — гетеродоксия, ext — экстремизм, mix — смешанная, gold — умма, ev/ev2 — события.
A14: Оговорки
A15: • Шкала — по десятилетиям; события одного десятилетия попадают в одну ячейку.
... A18: • Упоминание запрещённых организаций носит справочно-исторический характер.
